[2024-11-07 17:00:14,708] 224 werkzeug - INFO - [31m[1mWARNING: This is a development server. Do not use it in a production deployment. Use a production WSGI server instead.[0m
 * Running on all addresses (0.0.0.0)
 * Running on http://127.0.0.1:5001
 * Running on http://192.168.0.126:5001
[2024-11-07 17:00:14,708] 224 werkzeug - INFO - [33mPress CTRL+C to quit[0m
[2024-11-07 17:01:53,818] 224 werkzeug - INFO - 127.0.0.1 - - [07/Nov/2024 17:01:53] "GET / HTTP/1.1" 200 -
[2024-11-07 17:01:53,862] 224 werkzeug - INFO - 127.0.0.1 - - [07/Nov/2024 17:01:53] "[33mGET /favicon.ico HTTP/1.1[0m" 404 -
[2024-11-07 17:03:18,522] 224 werkzeug - INFO - 127.0.0.1 - - [07/Nov/2024 17:03:18] "GET / HTTP/1.1" 200 -
[2024-11-07 17:03:23,418] 224 werkzeug - INFO - 127.0.0.1 - - [07/Nov/2024 17:03:23] "GET / HTTP/1.1" 200 -
[2024-11-07 17:03:52,309] 224 werkzeug - INFO - 127.0.0.1 - - [07/Nov/2024 17:03:52] "[33mGET /predict_data HTTP/1.1[0m" 404 -
[2024-11-07 17:04:00,261] 1744 app - ERROR - Exception on /predictdata [GET]
Traceback (most recent call last):
  File "/opt/anaconda3/lib/python3.11/site-packages/flask/app.py", line 2529, in wsgi_app
    response = self.full_dispatch_request()
               ^^^^^^^^^^^^^^^^^^^^^^^^^^^^
  File "/opt/anaconda3/lib/python3.11/site-packages/flask/app.py", line 1825, in full_dispatch_request
    rv = self.handle_user_exception(e)
         ^^^^^^^^^^^^^^^^^^^^^^^^^^^^^
  File "/opt/anaconda3/lib/python3.11/site-packages/flask/app.py", line 1823, in full_dispatch_request
    rv = self.dispatch_request()
         ^^^^^^^^^^^^^^^^^^^^^^^
  File "/opt/anaconda3/lib/python3.11/site-packages/flask/app.py", line 1799, in dispatch_request
    return self.ensure_sync(self.view_functions[rule.endpoint])(**view_args)
           ^^^^^^^^^^^^^^^^^^^^^^^^^^^^^^^^^^^^^^^^^^^^^^^^^^^^^^^^^^^^^^^^^
  File "/Users/sachinbb/data_science/Ml_structure/app.py", line 21, in predict_datapoint
    return render_template('home.html')
           ^^^^^^^^^^^^^^^^^^^^^^^^^^^^
  File "/opt/anaconda3/lib/python3.11/site-packages/flask/templating.py", line 147, in render_template
    return _render(app, template, context)
           ^^^^^^^^^^^^^^^^^^^^^^^^^^^^^^^
  File "/opt/anaconda3/lib/python3.11/site-packages/flask/templating.py", line 130, in _render
    rv = template.render(context)
         ^^^^^^^^^^^^^^^^^^^^^^^^
  File "/opt/anaconda3/lib/python3.11/site-packages/jinja2/environment.py", line 1301, in render
    self.environment.handle_exception()
  File "/opt/anaconda3/lib/python3.11/site-packages/jinja2/environment.py", line 936, in handle_exception
    raise rewrite_traceback_stack(source=source)
  File "/Users/sachinbb/data_science/Ml_structure/templates/home.html", line 6, in top-level template code
    <form action="{{ url_for('predict_data')}}" method="post">
    ^^^^^^^^^^^^^^^^^^^^^^^^^
  File "/opt/anaconda3/lib/python3.11/site-packages/flask/app.py", line 2034, in url_for
    return self.handle_url_build_error(error, endpoint, values)
           ^^^^^^^^^^^^^^^^^^^^^^^^^^^^^^^^^^^^^^^^^^^^^^^^^^^^
  File "/opt/anaconda3/lib/python3.11/site-packages/flask/app.py", line 2023, in url_for
    rv = url_adapter.build(  # type: ignore[union-attr]
         ^^^^^^^^^^^^^^^^^^^^^^^^^^^^^^^^^^^^^^^^^^^^^^
  File "/opt/anaconda3/lib/python3.11/site-packages/werkzeug/routing/map.py", line 917, in build
    raise BuildError(endpoint, values, method, self)
werkzeug.routing.exceptions.BuildError: Could not build url for endpoint 'predict_data'. Did you mean 'predict_datapoint' instead?
[2024-11-07 17:04:00,269] 224 werkzeug - INFO - 127.0.0.1 - - [07/Nov/2024 17:04:00] "[35m[1mGET /predictdata HTTP/1.1[0m" 500 -
